<?xml version="1.0" ?>
<!-- =================================================================================== -->
<!-- |    This document was autogenerated by xacro from /home/oskars/workspace/ar4_pmb2_ws/src/pmb2_ar4_ros/pmb2_ar4_description/urdf/pmb2_ar4.urdf.xacro | -->
<!-- |    EDITING THIS FILE BY HAND IS NOT RECOMMENDED                                 | -->
<!-- =================================================================================== -->
<!-- 
  Copyright (c) 2024 PAL Robotics S.L. All rights reserved.

  Licensed under the Apache License, Version 2.0 (the "License");
  you may not use this file except in compliance with the License.
  You may obtain a copy of the License at

      http://www.apache.org/licenses/LICENSE-2.0

  Unless required by applicable law or agreed to in writing, software
  distributed under the License is distributed on an "AS IS" BASIS,
  WITHOUT WARRANTIES OR CONDITIONS OF ANY KIND, either express or implied.
  See the License for the specific language governing permissions and
  limitations under the License.
-->
<robot name="pmb2_ar4">
  <!-- ARGUMENTS -->
  <!-- PROPERTIES -->
  <!-- INCLUDES -->
  <!-- PROPERTIES -->
  <material name="Blue">
    <color rgba="0.0 0.0 0.8 1.0"/>
  </material>
  <material name="Green">
    <color rgba="0.0 0.8 0.0 1.0"/>
  </material>
  <material name="Grey">
    <color rgba="0.7 0.7 0.7 1.0"/>
  </material>
  <material name="LightGrey">
    <color rgba="0.9 0.9 0.9 1.0"/>
  </material>
  <material name="DarkGrey">
    <color rgba="0.1 0.1 0.1 1.0"/>
  </material>
  <material name="Red">
    <color rgba="0.8 0.0 0.0 1.0"/>
  </material>
  <material name="White">
    <color rgba="1.0 1.0 1.0 1.0"/>
  </material>
  <material name="Yellow">
    <color rgba="0.96 0.88 0.14 1.0"/>
  </material>
  <material name="Black">
    <color rgba="0.0 0.0 0.0 1.0"/>
  </material>
  <material name="FlatBlack">
    <color rgba="0.09 0.09 0.09 1.0"/>
  </material>
  <material name="Orange">
    <color rgba="1.0 0.487 0.0 1.0"/>
  </material>
  <material name="pal/Orange">
    <color rgba="0.91373 0.61568 0.29411 1.0"/>
  </material>
  <material name="pal/DarkGrey">
    <color rgba="0.29804 0.29804 0.29804 1"/>
  </material>
  <!-- ROS 2 Control -->
  <!-- <xacro:include filename="$(find pmb2_ar4_description)/urdf/pmb2_ar4.ros2_control.xacro" />
  <xacro:pmb2_ar4_ros2_control 
    ar_model="$(arg ar_model)"
    plugin_name="${plugin_name}"
    serial_port="${serial_port}"
    calibrate="${calibrate}"
    robot_parameters_file="$(find annin_ar4_description)/config/$(arg ar_model).yaml"
    joint_offset_parameters_file="$(find annin_ar4_driver)/config/joint_offsets/$(arg ar_model).yaml"
    driver_parameters_file="$(find annin_ar4_driver)/config/driver.yaml"
    tf_prefix="$(arg tf_prefix)"
  /> -->
  <ros2_control name="mk1" type="system">
    <hardware>
      <plugin>annin_ar4_driver/ARHardwareInterface</plugin>
      <param name="ar_model">mk1</param>
      <param name="serial_port">/dev/ttyACM0</param>
      <param name="calibrate">True</param>
      <param name="calib_sequence">1012345</param>
      <param name="velocity_control_enabled">True</param>
      <param name="tf_prefix">ar4_</param>
    </hardware>
    <joint name="ar4_joint_1">
      <command_interface name="position">
        <param name="min">-2.9670597283903604</param>
        <param name="max">2.9670597283903604</param>
      </command_interface>
      <command_interface name="velocity"/>
      <state_interface name="position">
        <param name="initial_value">0.0</param>
      </state_interface>
      <state_interface name="velocity">
        <param name="initial_value">0.0</param>
      </state_interface>
      <param name="position_offset">170.0</param>
    </joint>
    <joint name="ar4_joint_2">
      <command_interface name="position">
        <param name="min">-0.7330382858376184</param>
        <param name="max">1.5707963267948966</param>
      </command_interface>
      <command_interface name="velocity"/>
      <state_interface name="position">
        <param name="initial_value">0.0</param>
      </state_interface>
      <state_interface name="velocity">
        <param name="initial_value">0.0</param>
      </state_interface>
      <param name="position_offset">-42.0</param>
    </joint>
    <joint name="ar4_joint_3">
      <command_interface name="position">
        <param name="min">-1.5533430342749532</param>
        <param name="max">0.9075712110370514</param>
      </command_interface>
      <command_interface name="velocity"/>
      <state_interface name="position">
        <param name="initial_value">0.0</param>
      </state_interface>
      <state_interface name="velocity">
        <param name="initial_value">0.0</param>
      </state_interface>
      <param name="position_offset">-89.0</param>
    </joint>
    <joint name="ar4_joint_4">
      <command_interface name="position">
        <param name="min">-2.8797932657906435</param>
        <param name="max">2.8797932657906435</param>
      </command_interface>
      <command_interface name="velocity"/>
      <state_interface name="position">
        <param name="initial_value">0.0</param>
      </state_interface>
      <state_interface name="velocity">
        <param name="initial_value">0.0</param>
      </state_interface>
      <param name="position_offset">-165.0</param>
    </joint>
    <joint name="ar4_joint_5">
      <command_interface name="position">
        <param name="min">-1.8325957145940461</param>
        <param name="max">1.8325957145940461</param>
      </command_interface>
      <command_interface name="velocity"/>
      <state_interface name="position">
        <param name="initial_value">0.0</param>
      </state_interface>
      <state_interface name="velocity">
        <param name="initial_value">0.0</param>
      </state_interface>
      <param name="position_offset">-105.0</param>
    </joint>
    <joint name="ar4_joint_6">
      <command_interface name="position">
        <param name="min">-2.705260340591211</param>
        <param name="max">2.705260340591211</param>
      </command_interface>
      <command_interface name="velocity"/>
      <state_interface name="position">
        <param name="initial_value">0.0</param>
      </state_interface>
      <state_interface name="velocity">
        <param name="initial_value">0.0</param>
      </state_interface>
      <param name="position_offset">-155.0</param>
    </joint>
  </ros2_control>
  <ros2_control name="ar_servo_gripper" type="system">
    <hardware>
      <plugin>annin_ar4_driver/ARServoGripperHWInterface</plugin>
      <param name="serial_port">/dev/ttyUSB0</param>
      <param name="use_overcurrent_protection">False</param>
      <param name="closed_servo_angle">0</param>
      <param name="open_servo_angle">45</param>
      <param name="tf_prefix">ar4_</param>
    </hardware>
    <joint name="ar4_gripper_jaw1_joint">
      <command_interface name="position"/>
      <state_interface name="position">
        <param name="initial_value">0.0</param>
        <!-- <param name="initial_value">0.005</param> -->
      </state_interface>
      <state_interface name="velocity">
        <param name="initial_value">0.0</param>
      </state_interface>
    </joint>
    <joint name="ar4_gripper_jaw2_joint">
      <param name="mimic">ar4_gripper_jaw1_joint</param>
      <param name="multiplier">1</param>
      <state_interface name="position">
        <param name="initial_value">0.0</param>
        <!-- <param name="initial_value">0.005</param> -->
      </state_interface>
      <state_interface name="velocity">
        <param name="initial_value">0.0</param>
      </state_interface>
    </joint>
  </ros2_control>
  <!-- PMB2 -->
  <!-- <xacro:include filename="$(find pmb2_ar4_description)/urdf/pmb2_ros2_control.urdf.xacro" /> -->
  <!-- <xacro:pmb2_ros2_control use_sim_time="$(arg use_sim_time)" simulation_controllers="$(arg simulation_controllers)"/> -->
  <!-- <xacro:if value="${use_sim_time}">
    <gazebo>
      <plugin filename="libgazebo_ros2_control.so" name="gazebo_ros2_control">
        <parameters>$(arg simulation_controllers)</parameters>
      </plugin>
    </gazebo>
  </xacro:if> -->
  <!-- ROBOT DEFINITION -->
  <link name="base_imu_link">
    <inertial>
      <mass value="0.01"/>
      <origin xyz="0 0 0"/>
      <inertia ixx="0.000001" ixy="0" ixz="0" iyy="0.000001" iyz="0" izz="0.000001"/>
    </inertial>
  </link>
  <joint name="base_imu_joint" type="fixed">
    <parent link="base_link"/>
    <child link="base_imu_link"/>
    <origin rpy="0 0 -1.5707963267948966" xyz="0.10171 0 0.11282"/>
  </joint>
  <gazebo reference="base_imu_link">
    <sensor name="base_imu_sensor" type="imu">
      <always_on>1</always_on>
      <update_rate>100.0</update_rate>
      <imu>
        <noise>
          <type>gaussian</type>
          <rate>
            <mean>0.0</mean>
            <stddev>2e-4</stddev>
            <bias_mean>0.0000075</bias_mean>
            <bias_stddev>0.0000008</bias_stddev>
          </rate>
          <accel>
            <mean>0.0</mean>
            <stddev>1.7e-2</stddev>
            <bias_mean>0.1</bias_mean>
            <bias_stddev>0.001</bias_stddev>
          </accel>
        </noise>
      </imu>
      <plugin filename="libgazebo_ros_imu_sensor.so" name="base_imu">
        <ros>
          <!-- publish to /imu/data -->
          <remapping>~/out:=base_imu</remapping>
        </ros>
      </plugin>
    </sensor>
  </gazebo>
  <!-- Laser -->
  <link name="base_laser_link" type="laser">
    <inertial>
      <origin rpy="0 0 0" xyz="-0.02559000000 -0.00056000000 -0.05732000000"/>
      <mass value="0.28922000000"/>
      <inertia ixx="0.00002628919" ixy="0.00000024298" ixz="-0.00000368129" iyy="0.00003374542" iyz="-0.00000001330" izz="0.00005832599"/>
    </inertial>
    <visual>
      <origin rpy="0 0 0" xyz="0 0 0"/>
      <geometry>
        <mesh filename="package://pmb2_description/meshes/sensors/sick_tim551.stl"/>
      </geometry>
      <material name="DarkGrey"/>
    </visual>
  </link>
  <joint name="base_laser_joint" type="fixed">
    <axis xyz="0 1 0"/>
    <origin rpy="0 0 0" xyz="0.202 0.0 -0.004"/>
    <parent link="base_link"/>
    <child link="base_laser_link"/>
  </joint>
  <gazebo reference="base_laser_link">
    <sensor name="base_laser" type="ray">
      <pose>0 0 0 0 0 0</pose>
      <update_rate>10</update_rate>
      <visualize>true</visualize>
      <ray>
        <scan>
          <horizontal>
            <!-- 818 (270/0.33) steps in 270deg fov -->
            <samples>666.5185185185185</samples>
            <resolution>1</resolution>
            <!-- not the sensor resolution; just 1 -->
            <min_angle>-1.9198621771937625</min_angle>
            <max_angle>1.9198621771937625</max_angle>
          </horizontal>
        </scan>
        <range>
          <min>0.05</min>
          <max>25.0</max>
          <resolution>0.001</resolution>
        </range>
        <noise>
          <type>gaussian</type>
          <mean>0.0</mean>
          <stddev>0.01</stddev>
        </noise>
      </ray>
      <plugin filename="libgazebo_ros_ray_sensor.so" name="base_laser">
        <ros>
          <remapping>~/out:=scan_raw</remapping>
        </ros>
        <output_type>sensor_msgs/LaserScan</output_type>
        <frame_name>base_laser_link</frame_name>
      </plugin>
    </sensor>
    <material>Gazebo/DarkGrey</material>
  </gazebo>
  <link name="base_sonar_03_link">
    <inertial>
      <origin rpy="0 0 0" xyz="0 0 0"/>
      <mass value="0.001"/>
      <inertia ixx="0.000001" ixy="0" ixz="0" iyy="0.000001" iyz="0" izz="0.000001"/>
    </inertial>
    <visual>
      <origin rpy="0 0 0" xyz="0 0 0"/>
      <geometry>
        <mesh filename="package://pmb2_description/meshes/sensors/srf05.stl"/>
      </geometry>
      <material name="DarkGrey"/>
    </visual>
  </link>
  <joint name="base_sonar_03_joint" type="fixed">
    <origin rpy="0 0 2.356194490192345" xyz="-0.183 0.183 0.173"/>
    <axis xyz="0 0 1"/>
    <parent link="base_link"/>
    <child link="base_sonar_03_link"/>
  </joint>
  <gazebo reference="base_sonar_03_link">
    <sensor name="base_sonar_03" type="ray">
      <pose>0 0 0 0 0 0</pose>
      <update_rate>5</update_rate>
      <visualize>false</visualize>
      <ray>
        <scan>
          <horizontal>
            <samples>5</samples>
            <resolution>1</resolution>
            <min_angle>-0.25</min_angle>
            <max_angle>0.25</max_angle>
          </horizontal>
          <vertical>
            <samples>5</samples>
            <resolution>1</resolution>
            <min_angle>-0.25</min_angle>
            <max_angle>0.25</max_angle>
          </vertical>
        </scan>
        <range>
          <min>0.02</min>
          <max>1.0</max>
          <resolution>0.01</resolution>
        </range>
        <noise>
          <type>gaussian</type>
          <mean>0.0</mean>
          <stddev>0.005</stddev>
        </noise>
      </ray>
      <plugin filename="libgazebo_ros_ray_sensor.so" name="base_sonar_03_gazebo_ros_range">
        <ros>
          <namespace/>
          <remapping>~/out:=sonar_base</remapping>
        </ros>
        <output_type>sensor_msgs/Range</output_type>
        <radiation_type>ultrasound</radiation_type>
        <frame_name>base_sonar_03_link</frame_name>
      </plugin>
    </sensor>
    <material>Gazebo/DarkGrey</material>
  </gazebo>
  <link name="base_sonar_02_link">
    <inertial>
      <origin rpy="0 0 0" xyz="0 0 0"/>
      <mass value="0.001"/>
      <inertia ixx="0.000001" ixy="0" ixz="0" iyy="0.000001" iyz="0" izz="0.000001"/>
    </inertial>
    <visual>
      <origin rpy="0 0 0" xyz="0 0 0"/>
      <geometry>
        <mesh filename="package://pmb2_description/meshes/sensors/srf05.stl"/>
      </geometry>
      <material name="DarkGrey"/>
    </visual>
  </link>
  <joint name="base_sonar_02_joint" type="fixed">
    <origin rpy="0 0 3.141592653589793" xyz="-0.259 0.0 0.173"/>
    <axis xyz="0 0 1"/>
    <parent link="base_link"/>
    <child link="base_sonar_02_link"/>
  </joint>
  <gazebo reference="base_sonar_02_link">
    <sensor name="base_sonar_02" type="ray">
      <pose>0 0 0 0 0 0</pose>
      <update_rate>5</update_rate>
      <visualize>false</visualize>
      <ray>
        <scan>
          <horizontal>
            <samples>5</samples>
            <resolution>1</resolution>
            <min_angle>-0.25</min_angle>
            <max_angle>0.25</max_angle>
          </horizontal>
          <vertical>
            <samples>5</samples>
            <resolution>1</resolution>
            <min_angle>-0.25</min_angle>
            <max_angle>0.25</max_angle>
          </vertical>
        </scan>
        <range>
          <min>0.02</min>
          <max>1.0</max>
          <resolution>0.01</resolution>
        </range>
        <noise>
          <type>gaussian</type>
          <mean>0.0</mean>
          <stddev>0.005</stddev>
        </noise>
      </ray>
      <plugin filename="libgazebo_ros_ray_sensor.so" name="base_sonar_02_gazebo_ros_range">
        <ros>
          <namespace/>
          <remapping>~/out:=sonar_base</remapping>
        </ros>
        <output_type>sensor_msgs/Range</output_type>
        <radiation_type>ultrasound</radiation_type>
        <frame_name>base_sonar_02_link</frame_name>
      </plugin>
    </sensor>
    <material>Gazebo/DarkGrey</material>
  </gazebo>
  <link name="base_sonar_01_link">
    <inertial>
      <origin rpy="0 0 0" xyz="0 0 0"/>
      <mass value="0.001"/>
      <inertia ixx="0.000001" ixy="0" ixz="0" iyy="0.000001" iyz="0" izz="0.000001"/>
    </inertial>
    <visual>
      <origin rpy="0 0 0" xyz="0 0 0"/>
      <geometry>
        <mesh filename="package://pmb2_description/meshes/sensors/srf05.stl"/>
      </geometry>
      <material name="DarkGrey"/>
    </visual>
  </link>
  <joint name="base_sonar_01_joint" type="fixed">
    <origin rpy="0 0 3.9269908169872414" xyz="-0.183 -0.183 0.173"/>
    <axis xyz="0 0 1"/>
    <parent link="base_link"/>
    <child link="base_sonar_01_link"/>
  </joint>
  <gazebo reference="base_sonar_01_link">
    <sensor name="base_sonar_01" type="ray">
      <pose>0 0 0 0 0 0</pose>
      <update_rate>5</update_rate>
      <visualize>false</visualize>
      <ray>
        <scan>
          <horizontal>
            <samples>5</samples>
            <resolution>1</resolution>
            <min_angle>-0.25</min_angle>
            <max_angle>0.25</max_angle>
          </horizontal>
          <vertical>
            <samples>5</samples>
            <resolution>1</resolution>
            <min_angle>-0.25</min_angle>
            <max_angle>0.25</max_angle>
          </vertical>
        </scan>
        <range>
          <min>0.02</min>
          <max>1.0</max>
          <resolution>0.01</resolution>
        </range>
        <noise>
          <type>gaussian</type>
          <mean>0.0</mean>
          <stddev>0.005</stddev>
        </noise>
      </ray>
      <plugin filename="libgazebo_ros_ray_sensor.so" name="base_sonar_01_gazebo_ros_range">
        <ros>
          <namespace/>
          <remapping>~/out:=sonar_base</remapping>
        </ros>
        <output_type>sensor_msgs/Range</output_type>
        <radiation_type>ultrasound</radiation_type>
        <frame_name>base_sonar_01_link</frame_name>
      </plugin>
    </sensor>
    <material>Gazebo/DarkGrey</material>
  </gazebo>
  <!-- Base -->
  <link name="base_link">
    <inertial>
      <origin rpy="0 0 0" xyz="-0.00000106 0.00000109 0.0000387"/>
      <mass value="28.26649"/>
      <inertia ixx="0.465408937" ixy="0.002160024" ixz="-0.001760255" iyy="0.483193291" iyz="-0.000655952" izz="0.550939703"/>
    </inertial>
    <visual>
      <origin rpy="0 0 0" xyz="0 0 0"/>
      <geometry>
        <mesh filename="package://pmb2_description/meshes/base/base.stl"/>
      </geometry>
      <material name="White"/>
    </visual>
    <collision>
      <origin rpy="0 0 0" xyz="0 0 0"/>
      <geometry>
        <mesh filename="package://pmb2_description/meshes/base/high_resolution/base_collision.stl"/>
      </geometry>
      <material name="White"/>
    </collision>
  </link>
  <!-- Base footprint -->
  <link name="base_footprint"/>
  <joint name="base_footprint_joint" type="fixed">
    <origin rpy="0 0 0" xyz="0 0 0.0985"/>
    <child link="base_link"/>
    <parent link="base_footprint"/>
  </joint>
  <link name="base_cover_link">
    <inertial>
      <origin rpy="0 0 0" xyz="0.22414000000 0.00002000000 0.04681000000"/>
      <mass value="0.25821000000"/>
      <inertia ixx="0.00023719188" ixy="0.00000006119" ixz="-0.00000011799" iyy="0.00028335052" iyz="0.00000000774" izz="0.00038497063"/>
    </inertial>
    <visual>
      <origin rpy="0 0 0" xyz="0 0 0"/>
      <geometry>
        <mesh filename="package://pmb2_description/meshes/base/base_ring.stl"/>
      </geometry>
      <material name="Orange"/>
    </visual>
  </link>
  <joint name="cover_joint" type="fixed">
    <parent link="base_footprint"/>
    <child link="base_cover_link"/>
    <origin rpy="0 0 0" xyz="0 0 0.13"/>
  </joint>
  <gazebo reference="base_cover_link">
    <material>Gazebo/Orange</material>
  </gazebo>
  <!-- Docking link -->
  <link name="base_dock_link">
    <inertial>
      <origin rpy="0 0 0" xyz="-0.0037082 1.5226E-18 -4.1633E-17"/>
      <mass value="0.032242"/>
      <inertia ixx="2.1302E-05" ixy="-1.0461E-21" ixz="6.6555E-22" iyy="1.2058E-05" iyz="-1.9453E-21" izz="1.0058E-05"/>
    </inertial>
    <visual>
      <origin rpy="0 0 0" xyz="0 0 0"/>
      <geometry>
        <mesh filename="package://pmb2_description/meshes/base/base_dock_link.stl"/>
      </geometry>
      <material name="">
        <color rgba="0.25098 0.25098 0.25098 1"/>
      </material>
    </visual>
    <collision>
      <origin rpy="0 0 0" xyz="0 0 0"/>
      <geometry>
        <mesh filename="package://pmb2_description/meshes/base/base_dock_link.stl"/>
      </geometry>
    </collision>
  </link>
  <joint name="base_dock" type="fixed">
    <origin rpy="0 0 0" xyz="0.2675 0 0.061"/>
    <parent link="base_link"/>
    <child link="base_dock_link"/>
    <axis xyz="0 0 0"/>
  </joint>
  <link name="base_antenna_left_link">
    <inertial>
      <origin rpy="0 0 0" xyz="0 0 0"/>
      <mass value="0.000001"/>
      <inertia ixx="0.00000002371" ixy="0.00000006119" ixz="0.00000001179" iyy="0.00000002833" iyz="0.00000000774" izz="0.00000003849"/>
    </inertial>
    <visual>
      <origin rpy="0 0 0" xyz="0 0 0"/>
      <geometry>
        <mesh filename="package://pmb2_description/meshes/objects/antenna.stl"/>
      </geometry>
      <material name="Black"/>
    </visual>
    <collision>
      <origin rpy="0 0 0" xyz="0 0 0.085"/>
      <geometry>
        <cylinder length="0.17" radius="0.005"/>
      </geometry>
      <material name="Black"/>
    </collision>
  </link>
  <gazebo reference="base_antenna_left_link">
    <material>Gazebo/Black</material>
  </gazebo>
  <joint name="base_antenna_left_joint" type="fixed">
    <parent link="base_link"/>
    <child link="base_antenna_left_link"/>
    <origin rpy="0 0 0" xyz="-0.201 0.1062 0.195"/>
  </joint>
  <link name="base_antenna_right_link">
    <inertial>
      <origin rpy="0 0 0" xyz="0 0 0"/>
      <mass value="0.000001"/>
      <inertia ixx="0.00000002371" ixy="0.00000006119" ixz="0.00000001179" iyy="0.00000002833" iyz="0.00000000774" izz="0.00000003849"/>
    </inertial>
    <visual>
      <origin rpy="0 0 0" xyz="0 0 0"/>
      <geometry>
        <mesh filename="package://pmb2_description/meshes/objects/antenna.stl"/>
      </geometry>
      <material name="Black"/>
    </visual>
    <collision>
      <origin rpy="0 0 0" xyz="0 0 0.085"/>
      <geometry>
        <cylinder length="0.17" radius="0.005"/>
      </geometry>
      <material name="Black"/>
    </collision>
  </link>
  <gazebo reference="base_antenna_right_link">
    <material>Gazebo/Black</material>
  </gazebo>
  <joint name="base_antenna_right_joint" type="fixed">
    <parent link="base_link"/>
    <child link="base_antenna_right_link"/>
    <origin rpy="0 0 0" xyz="-0.201 -0.1062 0.195"/>
  </joint>
  <link name="wheel_right_link">
    <inertial>
      <origin rpy="0 0 0" xyz="0 0 -0.00207"/>
      <mass value="1.82362"/>
      <inertia ixx="0.00499743171" ixy="4.464e-08" ixz="-0.00000002245" iyy="0.00499741733" iyz="-1.64e-09" izz="0.00839239692"/>
    </inertial>
    <visual>
      <origin rpy="-0.0 0 0" xyz="0 0 0"/>
      <geometry>
        <mesh filename="package://pmb2_description/meshes/wheels/wheel.stl"/>
      </geometry>
      <material name="DarkGrey"/>
    </visual>
    <collision>
      <origin rpy="0 0 0" xyz="0 0 0"/>
      <geometry>
        <cylinder length="0.04" radius="0.0985"/>
      </geometry>
    </collision>
  </link>
  <link name="suspension_right_link">
    <inertial>
      <origin rpy="0 0 0" xyz="0 0 -0.02"/>
      <mass value="10"/>
      <inertia ixx="1.0" ixy="0" ixz="0" iyy="1.0" iyz="0" izz="1.0"/>
    </inertial>
    <kinematic>0</kinematic>
    <gravity>1</gravity>
  </link>
  <joint name="suspension_right_joint" type="fixed">
    <origin rpy="0 0 0" xyz="0 0 0"/>
    <axis xyz="0 0 1"/>
    <child link="suspension_right_link"/>
    <parent link="base_link"/>
  </joint>
  <joint name="wheel_right_joint" type="continuous">
    <parent link="suspension_right_link"/>
    <child link="wheel_right_link"/>
    <origin rpy="-1.5707963267948966 0 0" xyz="0 -0.2022 0.0"/>
    <axis xyz="0 0 1"/>
    <limit effort="6.0" velocity="10.152284263959391"/>
    <dynamics damping="1.0" friction="2.0"/>
  </joint>
  <!-- Contact model for the wheel surface -->
  <gazebo reference="wheel_right_link">
    <mu1>1.0</mu1>
    <mu2>1.0</mu2>
    <kp>1000000.0</kp>
    <kd>100.0</kd>
    <minDepth>0.002</minDepth>
    <maxVel>1.0</maxVel>
    <material>Gazebo/DarkGrey</material>
  </gazebo>
  <link name="wheel_left_link">
    <inertial>
      <origin rpy="0 0 0" xyz="0 0 0.00207"/>
      <mass value="1.82362"/>
      <inertia ixx="0.00499743171" ixy="-4.464e-08" ixz="-0.00000002245" iyy="0.00499741733" iyz="1.64e-09" izz="0.00839239692"/>
    </inertial>
    <visual>
      <origin rpy="-3.141592653589793 0 0" xyz="0 0 0"/>
      <geometry>
        <mesh filename="package://pmb2_description/meshes/wheels/wheel.stl"/>
      </geometry>
      <material name="DarkGrey"/>
    </visual>
    <collision>
      <origin rpy="0 0 0" xyz="0 0 0"/>
      <geometry>
        <cylinder length="0.04" radius="0.0985"/>
      </geometry>
    </collision>
  </link>
  <link name="suspension_left_link">
    <inertial>
      <origin rpy="0 0 0" xyz="0 0 -0.02"/>
      <mass value="10"/>
      <inertia ixx="1.0" ixy="0" ixz="0" iyy="1.0" iyz="0" izz="1.0"/>
    </inertial>
    <kinematic>0</kinematic>
    <gravity>1</gravity>
  </link>
  <joint name="suspension_left_joint" type="fixed">
    <origin rpy="0 0 0" xyz="0 0 0"/>
    <axis xyz="0 0 1"/>
    <child link="suspension_left_link"/>
    <parent link="base_link"/>
  </joint>
  <joint name="wheel_left_joint" type="continuous">
    <parent link="suspension_left_link"/>
    <child link="wheel_left_link"/>
    <origin rpy="-1.5707963267948966 0 0" xyz="0 0.2022 0.0"/>
    <axis xyz="0 0 1"/>
    <limit effort="6.0" velocity="10.152284263959391"/>
    <dynamics damping="1.0" friction="2.0"/>
  </joint>
  <!-- Contact model for the wheel surface -->
  <gazebo reference="wheel_left_link">
    <mu1>1.0</mu1>
    <mu2>1.0</mu2>
    <kp>1000000.0</kp>
    <kd>100.0</kd>
    <minDepth>0.002</minDepth>
    <maxVel>1.0</maxVel>
    <material>Gazebo/DarkGrey</material>
  </gazebo>
  <link name="caster_front_right_1_link">
    <inertial>
      <origin rpy="0 0 0" xyz="-0.00634599 0.00005347 -0.02037519"/>
      <mass value="0.05144761"/>
      <inertia ixx="0.00001513" ixy="-0.00000003" ixz="0.00000267" iyy="0.00001309" iyz="-0.00000005" izz="0.00001198"/>
    </inertial>
    <visual>
      <origin rpy="0 0 0" xyz="0 0 0"/>
      <geometry>
        <mesh filename="package://pmb2_description/meshes/wheels/caster_1.stl"/>
      </geometry>
      <material name="Grey"/>
    </visual>
    <!--collision>
        <origin xyz="0 0 0" rpy="0 0 0"/>
        <geometry>
          <cylinder radius="${radius}" length="${width}"/>
        </geometry>
      </collision-->
  </link>
  <link name="caster_front_right_2_link">
    <inertial>
      <origin rpy="0 0 0" xyz="0 0 0"/>
      <mass value="0.08855784"/>
      <inertia ixx="0.00001075" ixy="0" ixz="0" iyy="0.00001541" iyz="0" izz="0.00001075"/>
    </inertial>
    <visual>
      <origin rpy="0 0 0" xyz="0 0 0"/>
      <geometry>
        <mesh filename="package://pmb2_description/meshes/wheels/caster_2.stl"/>
      </geometry>
      <material name="DarkGrey"/>
    </visual>
    <collision>
      <origin rpy="0 0 0" xyz="0 0 0"/>
      <geometry>
        <sphere radius="0.025"/>
      </geometry>
    </collision>
  </link>
  <joint name="caster_front_right_1_joint" type="fixed">
    <parent link="base_link"/>
    <child link="caster_front_right_1_link"/>
    <origin rpy="0 0 0" xyz="0.1695 -0.102 -0.0335"/>
    <axis xyz="0 0 1"/>
  </joint>
  <joint name="caster_front_right_2_joint" type="fixed">
    <parent link="caster_front_right_1_link"/>
    <child link="caster_front_right_2_link"/>
    <origin rpy="-1.5707963267948966 0 0" xyz="-0.016 0.0000 -0.040"/>
    <axis xyz="0 0 1"/>
  </joint>
  <!-- Contact model for the caster wheel surface -->
  <gazebo reference="caster_front_right_2_link">
    <mu1>0.01</mu1>
    <mu2>0.01</mu2>
    <kp>1000000.0</kp>
    <kd>100.0</kd>
    <minDepth>0.002</minDepth>
    <maxVel>1.0</maxVel>
    <material>Gazebo/DarkGrey</material>
  </gazebo>
  <link name="caster_front_left_1_link">
    <inertial>
      <origin rpy="0 0 0" xyz="-0.00634599 0.00005347 -0.02037519"/>
      <mass value="0.05144761"/>
      <inertia ixx="0.00001513" ixy="-0.00000003" ixz="0.00000267" iyy="0.00001309" iyz="-0.00000005" izz="0.00001198"/>
    </inertial>
    <visual>
      <origin rpy="0 0 0" xyz="0 0 0"/>
      <geometry>
        <mesh filename="package://pmb2_description/meshes/wheels/caster_1.stl"/>
      </geometry>
      <material name="Grey"/>
    </visual>
    <!--collision>
        <origin xyz="0 0 0" rpy="0 0 0"/>
        <geometry>
          <cylinder radius="${radius}" length="${width}"/>
        </geometry>
      </collision-->
  </link>
  <link name="caster_front_left_2_link">
    <inertial>
      <origin rpy="0 0 0" xyz="0 0 0"/>
      <mass value="0.08855784"/>
      <inertia ixx="0.00001075" ixy="0" ixz="0" iyy="0.00001541" iyz="0" izz="0.00001075"/>
    </inertial>
    <visual>
      <origin rpy="0 0 0" xyz="0 0 0"/>
      <geometry>
        <mesh filename="package://pmb2_description/meshes/wheels/caster_2.stl"/>
      </geometry>
      <material name="DarkGrey"/>
    </visual>
    <collision>
      <origin rpy="0 0 0" xyz="0 0 0"/>
      <geometry>
        <sphere radius="0.025"/>
      </geometry>
    </collision>
  </link>
  <joint name="caster_front_left_1_joint" type="fixed">
    <parent link="base_link"/>
    <child link="caster_front_left_1_link"/>
    <origin rpy="0 0 0" xyz="0.1695 0.102 -0.0335"/>
    <axis xyz="0 0 1"/>
  </joint>
  <joint name="caster_front_left_2_joint" type="fixed">
    <parent link="caster_front_left_1_link"/>
    <child link="caster_front_left_2_link"/>
    <origin rpy="-1.5707963267948966 0 0" xyz="-0.016 0.0000 -0.040"/>
    <axis xyz="0 0 1"/>
  </joint>
  <!-- Contact model for the caster wheel surface -->
  <gazebo reference="caster_front_left_2_link">
    <mu1>0.01</mu1>
    <mu2>0.01</mu2>
    <kp>1000000.0</kp>
    <kd>100.0</kd>
    <minDepth>0.002</minDepth>
    <maxVel>1.0</maxVel>
    <material>Gazebo/DarkGrey</material>
  </gazebo>
  <link name="caster_back_right_1_link">
    <inertial>
      <origin rpy="0 0 0" xyz="-0.00634599 0.00005347 -0.02037519"/>
      <mass value="0.05144761"/>
      <inertia ixx="0.00001513" ixy="-0.00000003" ixz="0.00000267" iyy="0.00001309" iyz="-0.00000005" izz="0.00001198"/>
    </inertial>
    <visual>
      <origin rpy="0 0 0" xyz="0 0 0"/>
      <geometry>
        <mesh filename="package://pmb2_description/meshes/wheels/caster_1.stl"/>
      </geometry>
      <material name="Grey"/>
    </visual>
    <!--collision>
        <origin xyz="0 0 0" rpy="0 0 0"/>
        <geometry>
          <cylinder radius="${radius}" length="${width}"/>
        </geometry>
      </collision-->
  </link>
  <link name="caster_back_right_2_link">
    <inertial>
      <origin rpy="0 0 0" xyz="0 0 0"/>
      <mass value="0.08855784"/>
      <inertia ixx="0.00001075" ixy="0" ixz="0" iyy="0.00001541" iyz="0" izz="0.00001075"/>
    </inertial>
    <visual>
      <origin rpy="0 0 0" xyz="0 0 0"/>
      <geometry>
        <mesh filename="package://pmb2_description/meshes/wheels/caster_2.stl"/>
      </geometry>
      <material name="DarkGrey"/>
    </visual>
    <collision>
      <origin rpy="0 0 0" xyz="0 0 0"/>
      <geometry>
        <sphere radius="0.025"/>
      </geometry>
    </collision>
  </link>
  <joint name="caster_back_right_1_joint" type="fixed">
    <parent link="base_link"/>
    <child link="caster_back_right_1_link"/>
    <origin rpy="0 0 0" xyz="-0.17350000000000002 -0.102 -0.0335"/>
    <axis xyz="0 0 1"/>
  </joint>
  <joint name="caster_back_right_2_joint" type="fixed">
    <parent link="caster_back_right_1_link"/>
    <child link="caster_back_right_2_link"/>
    <origin rpy="-1.5707963267948966 0 0" xyz="-0.016 0.0000 -0.040"/>
    <axis xyz="0 0 1"/>
  </joint>
  <!-- Contact model for the caster wheel surface -->
  <gazebo reference="caster_back_right_2_link">
    <mu1>0.01</mu1>
    <mu2>0.01</mu2>
    <kp>1000000.0</kp>
    <kd>100.0</kd>
    <minDepth>0.002</minDepth>
    <maxVel>1.0</maxVel>
    <material>Gazebo/DarkGrey</material>
  </gazebo>
  <link name="caster_back_left_1_link">
    <inertial>
      <origin rpy="0 0 0" xyz="-0.00634599 0.00005347 -0.02037519"/>
      <mass value="0.05144761"/>
      <inertia ixx="0.00001513" ixy="-0.00000003" ixz="0.00000267" iyy="0.00001309" iyz="-0.00000005" izz="0.00001198"/>
    </inertial>
    <visual>
      <origin rpy="0 0 0" xyz="0 0 0"/>
      <geometry>
        <mesh filename="package://pmb2_description/meshes/wheels/caster_1.stl"/>
      </geometry>
      <material name="Grey"/>
    </visual>
    <!--collision>
        <origin xyz="0 0 0" rpy="0 0 0"/>
        <geometry>
          <cylinder radius="${radius}" length="${width}"/>
        </geometry>
      </collision-->
  </link>
  <link name="caster_back_left_2_link">
    <inertial>
      <origin rpy="0 0 0" xyz="0 0 0"/>
      <mass value="0.08855784"/>
      <inertia ixx="0.00001075" ixy="0" ixz="0" iyy="0.00001541" iyz="0" izz="0.00001075"/>
    </inertial>
    <visual>
      <origin rpy="0 0 0" xyz="0 0 0"/>
      <geometry>
        <mesh filename="package://pmb2_description/meshes/wheels/caster_2.stl"/>
      </geometry>
      <material name="DarkGrey"/>
    </visual>
    <collision>
      <origin rpy="0 0 0" xyz="0 0 0"/>
      <geometry>
        <sphere radius="0.025"/>
      </geometry>
    </collision>
  </link>
  <joint name="caster_back_left_1_joint" type="fixed">
    <parent link="base_link"/>
    <child link="caster_back_left_1_link"/>
    <origin rpy="0 0 0" xyz="-0.17350000000000002 0.102 -0.0335"/>
    <axis xyz="0 0 1"/>
  </joint>
  <joint name="caster_back_left_2_joint" type="fixed">
    <parent link="caster_back_left_1_link"/>
    <child link="caster_back_left_2_link"/>
    <origin rpy="-1.5707963267948966 0 0" xyz="-0.016 0.0000 -0.040"/>
    <axis xyz="0 0 1"/>
  </joint>
  <!-- Contact model for the caster wheel surface -->
  <gazebo reference="caster_back_left_2_link">
    <mu1>0.01</mu1>
    <mu2>0.01</mu2>
    <kp>1000000.0</kp>
    <kd>100.0</kd>
    <minDepth>0.002</minDepth>
    <maxVel>1.0</maxVel>
    <material>Gazebo/DarkGrey</material>
  </gazebo>
  <!-- Materials -->
  <gazebo reference="base_link">
    <material>Gazebo/White</material>
  </gazebo>
  <!-- base_link through base_footprint-->
  <gazebo reference="base_footprint">
    <kp>100000000.0</kp>
    <kd>10.0</kd>
    <mu1>0.1</mu1>
    <mu2>0.1</mu2>
    <fdir1>1 0 0</fdir1>
    <maxVel>10.0</maxVel>
    <minDepth>0.0005</minDepth>
    <laserRetro>0</laserRetro>
  </gazebo>
  <!-- Odometry plugin for ground truth -->
  <gazebo>
    <plugin filename="libgazebo_world_odometry.so" name="gazebo_ros_odometry">
      <frame_name>world</frame_name>
      <body_name>base_footprint</body_name>
      <topic_name>ground_truth_odom</topic_name>
      <update_rate>100.0</update_rate>
    </plugin>
  </gazebo>
  <!-- Base top -->
  <link name="base_top"/>
  <joint name="base_top_joint" type="fixed">
    <origin rpy="0 0 0" xyz="0 0 0.2015"/>
    <child link="base_top"/>
    <parent link="base_link"/>
  </joint>
  <!-- Fixture Definition -->
  <link name="fixture_base">
    <visual>
      <origin rpy="0 0 0" xyz="0 0 0"/>
      <geometry>
        <mesh filename="file:///home/oskars/workspace/ar4_pmb2_ws/install/pmb2_ar4_description/share/pmb2_ar4_description/meshes/fixture/pmb2_ar4_fixture.STL"/>
      </geometry>
      <material name="gray">
        <color rgba="0.5 0.5 0.5 1"/>
      </material>
    </visual>
    <collision>
      <origin rpy="0 0 0" xyz="0 0 0"/>
      <geometry>
        <mesh filename="file:///home/oskars/workspace/ar4_pmb2_ws/install/pmb2_ar4_description/share/pmb2_ar4_description/meshes/fixture/pmb2_ar4_fixture.STL"/>
      </geometry>
    </collision>
    <inertial>
      <mass value="1.0"/>
      <origin xyz="0 0 0"/>
      <inertia ixx="0.01" ixy="0" ixz="0" iyy="0.01" iyz="0" izz="0.01"/>
    </inertial>
  </link>
  <!-- Joint to Attach Fixture to Base -->
  <joint name="base_to_fixture" type="fixed">
    <parent link="base_top"/>
    <child link="fixture_base"/>
    <origin rpy="0 0 0" xyz="0 0 0"/>
  </joint>
  <!-- Define the Top of the Fixture -->
  <link name="fixture_top"/>
  <joint name="fixture_to_top" type="fixed">
    <parent link="fixture_base"/>
    <child link="fixture_top"/>
    <origin rpy="0 0 1.57" xyz="0 0 0.284"/>
  </joint>
  <joint name="ar4_base_joint" type="fixed">
    <origin rpy="0 0 0" xyz="0 0 0"/>
    <parent link="fixture_top"/>
    <child link="ar4_base_link"/>
  </joint>
  <link name="ar4_base_link">
    <inertial>
      <origin rpy="0 0 0" xyz="-4.6941E-06 0.054174 0.038824"/>
      <mass value="0.7102"/>
      <inertia ixx="0.0039943" ixy="3.697E-07" ixz="-5.7364E-08" iyy="0.0014946" iyz="-0.00036051" izz="0.0042554"/>
    </inertial>
    <visual>
      <origin rpy="0 0 0" xyz="0 0 0"/>
      <geometry>
        <mesh filename="file:///home/oskars/workspace/ar4_pmb2_ws/install/annin_ar4_description/share/annin_ar4_description/meshes/ar4/base_link.STL"/>
      </geometry>
      <material name="">
        <color rgba="1 1 0 1"/>
      </material>
    </visual>
    <collision>
      <origin rpy="0 0 0" xyz="0 0 0"/>
      <geometry>
        <mesh filename="file:///home/oskars/workspace/ar4_pmb2_ws/install/annin_ar4_description/share/annin_ar4_description/meshes/ar4/base_link.STL"/>
      </geometry>
    </collision>
  </link>
  <link name="ar4_link_1">
    <inertial>
      <origin rpy="0 0 0" xyz="-0.022706 0.04294 -0.12205"/>
      <mass value="0.88065"/>
      <inertia ixx="0.0034" ixy="0.00042296" ixz="-0.00089231" iyy="0.0041778" iyz="0.0010848" izz="0.0027077"/>
    </inertial>
    <visual>
      <origin rpy="0 0 0" xyz="0 0 0"/>
      <geometry>
        <mesh filename="file:///home/oskars/workspace/ar4_pmb2_ws/install/annin_ar4_description/share/annin_ar4_description/meshes/ar4/link_1.STL"/>
      </geometry>
      <material name="">
        <color rgba="1 1 0 1"/>
      </material>
    </visual>
    <collision>
      <origin rpy="0 0 0" xyz="0 0 0"/>
      <geometry>
        <mesh filename="file:///home/oskars/workspace/ar4_pmb2_ws/install/annin_ar4_description/share/annin_ar4_description/meshes/ar4/link_1.STL"/>
      </geometry>
    </collision>
  </link>
  <joint name="ar4_joint_1" type="revolute">
    <origin rpy="3.141592653589793 0 0" xyz="0 0 0"/>
    <parent link="ar4_base_link"/>
    <child link="ar4_link_1"/>
    <axis xyz="0 0 1"/>
    <limit effort="1000" lower="-2.9670597283903604" upper="2.9670597283903604" velocity="1.0472"/>
  </joint>
  <link name="ar4_link_2">
    <inertial>
      <origin rpy="0 0 0" xyz="0.064818 -0.11189 -0.038671"/>
      <mass value="0.57738"/>
      <inertia ixx="0.0047312" ixy="0.0022624" ixz="0.00032144" iyy="0.0020836" iyz="-0.00056569" izz="0.0056129"/>
    </inertial>
    <visual>
      <origin rpy="0 0 0" xyz="0 0 0"/>
      <geometry>
        <mesh filename="file:///home/oskars/workspace/ar4_pmb2_ws/install/annin_ar4_description/share/annin_ar4_description/meshes/ar4/link_2.STL"/>
      </geometry>
      <material name="">
        <color rgba="1 1 0 1"/>
      </material>
    </visual>
    <collision>
      <origin rpy="0 0 0" xyz="0 0 0"/>
      <geometry>
        <mesh filename="file:///home/oskars/workspace/ar4_pmb2_ws/install/annin_ar4_description/share/annin_ar4_description/meshes/ar4/link_2.STL"/>
      </geometry>
    </collision>
  </link>
  <joint name="ar4_joint_2" type="revolute">
    <origin rpy="1.5708 0 -1.5708" xyz="0 0.0642 -0.16977"/>
    <parent link="ar4_link_1"/>
    <child link="ar4_link_2"/>
    <axis xyz="0 0 -1"/>
    <limit effort="1000" lower="-0.7330382858376184" upper="1.5707963267948966" velocity="1.0472"/>
  </joint>
  <link name="ar4_link_3">
    <inertial>
      <origin rpy="0 0 0" xyz="-0.00029765 -0.023661 -0.0019125"/>
      <mass value="0.1787"/>
      <inertia ixx="0.0001685" ixy="-2.7713E-05" ixz="5.6885E-06" iyy="0.00012865" iyz="2.9256E-05" izz="0.00020744"/>
    </inertial>
    <visual>
      <origin rpy="0 0 0" xyz="0 0 0"/>
      <geometry>
        <mesh filename="file:///home/oskars/workspace/ar4_pmb2_ws/install/annin_ar4_description/share/annin_ar4_description/meshes/ar4/link_3.STL"/>
      </geometry>
      <material name="">
        <color rgba="1 1 0 1"/>
      </material>
    </visual>
    <collision>
      <origin rpy="0 0 0" xyz="0 0 0"/>
      <geometry>
        <mesh filename="file:///home/oskars/workspace/ar4_pmb2_ws/install/annin_ar4_description/share/annin_ar4_description/meshes/ar4/link_3.STL"/>
      </geometry>
    </collision>
  </link>
  <joint name="ar4_joint_3" type="revolute">
    <origin rpy="0 0 3.1416" xyz="0 -0.305 0.007"/>
    <parent link="ar4_link_2"/>
    <child link="ar4_link_3"/>
    <axis xyz="0 0 -1"/>
    <limit effort="1000" lower="-1.5533430342749532" upper="0.9075712110370514" velocity="1.0472"/>
  </joint>
  <link name="ar4_link_4">
    <inertial>
      <origin rpy="0 0 0" xyz="-0.0016798 -0.00057319 -0.074404"/>
      <mass value="0.34936"/>
      <inertia ixx="0.0030532" ixy="-1.8615E-05" ixz="-7.0047E-05" iyy="0.0031033" iyz="-2.3301E-05" izz="0.00022264"/>
    </inertial>
    <visual>
      <origin rpy="0 0 0" xyz="0 0 0"/>
      <geometry>
        <mesh filename="file:///home/oskars/workspace/ar4_pmb2_ws/install/annin_ar4_description/share/annin_ar4_description/meshes/ar4/link_4.STL"/>
      </geometry>
      <material name="">
        <color rgba="1 1 0 1"/>
      </material>
    </visual>
    <collision>
      <origin rpy="0 0 0" xyz="0 0 0"/>
      <geometry>
        <mesh filename="file:///home/oskars/workspace/ar4_pmb2_ws/install/annin_ar4_description/share/annin_ar4_description/meshes/ar4/link_4.STL"/>
      </geometry>
    </collision>
  </link>
  <joint name="ar4_joint_4" type="revolute">
    <origin rpy="1.5708 0 -1.5708" xyz="0 0 0.0"/>
    <parent link="ar4_link_3"/>
    <child link="ar4_link_4"/>
    <axis xyz="0 0 -1"/>
    <limit effort="1000" lower="-2.8797932657906435" upper="2.8797932657906435" velocity="1.0472"/>
  </joint>
  <link name="ar4_link_5">
    <inertial>
      <origin rpy="0 0 0" xyz="0.0015066 -1.3102E-05 -0.012585"/>
      <mass value="0.11562"/>
      <inertia ixx="5.5035E-05" ixy="-1.019E-08" ixz="-2.6243E-06" iyy="8.2921E-05" iyz="1.4437E-08" izz="5.2518E-05"/>
    </inertial>
    <visual>
      <origin rpy="0 0 0" xyz="0 0 0"/>
      <geometry>
        <mesh filename="file:///home/oskars/workspace/ar4_pmb2_ws/install/annin_ar4_description/share/annin_ar4_description/meshes/ar4/link_5.STL"/>
      </geometry>
      <material name="">
        <color rgba="1 1 0 1"/>
      </material>
    </visual>
    <collision>
      <origin rpy="0 0 0" xyz="0 0 0"/>
      <geometry>
        <mesh filename="file:///home/oskars/workspace/ar4_pmb2_ws/install/annin_ar4_description/share/annin_ar4_description/meshes/ar4/link_5.STL"/>
      </geometry>
    </collision>
  </link>
  <joint name="ar4_joint_5" type="revolute">
    <origin rpy="3.141592653589793 0 -1.5708" xyz="0 0 -0.22263"/>
    <parent link="ar4_link_4"/>
    <child link="ar4_link_5"/>
    <axis xyz="1 0 0"/>
    <limit effort="1000" lower="-1.8325957145940461" upper="1.8325957145940461" velocity="1.0472"/>
  </joint>
  <link name="ar4_link_6">
    <inertial>
      <origin rpy="0 0 0" xyz="2.9287E-10 -1.6472E-09 0.0091432"/>
      <mass value="0.013863"/>
      <inertia ixx="1.3596E-06" ixy="3.0585E-13" ixz="5.7102E-14" iyy="1.7157E-06" iyz="6.3369E-09" izz="2.4332E-06"/>
    </inertial>
    <visual>
      <origin rpy="0 0 0" xyz="0 0 0"/>
      <geometry>
        <mesh filename="file:///home/oskars/workspace/ar4_pmb2_ws/install/annin_ar4_description/share/annin_ar4_description/meshes/ar4/link_6.STL"/>
      </geometry>
      <material name="">
        <color rgba="1 1 0 1"/>
      </material>
    </visual>
    <collision>
      <origin rpy="0 0 0" xyz="0 0 0"/>
      <geometry>
        <mesh filename="file:///home/oskars/workspace/ar4_pmb2_ws/install/annin_ar4_description/share/annin_ar4_description/meshes/ar4/link_6.STL"/>
      </geometry>
    </collision>
  </link>
  <joint name="ar4_joint_6" type="revolute">
    <origin rpy="0 0 3.1416" xyz="0.000 0 0.03625"/>
    <parent link="ar4_link_5"/>
    <child link="ar4_link_6"/>
    <axis xyz="0 0 1"/>
    <limit effort="1000" lower="-2.705260340591211" upper="2.705260340591211" velocity="1.0472"/>
  </joint>
  <joint name="ar4_camera_holder_joint" type="fixed">
    <origin rpy="-3.14 1.57 0.0" xyz="-0.025 -0.01104 -0.13135"/>
    <parent link="ar4_link_4"/>
    <child link="ar4_camera_holder_link"/>
  </joint>
  <link name="ar4_camera_holder_link">
    <visual>
      <geometry>
        <!-- <mesh filename="file://$(find annin_ar4_description)/meshes/ar4/J6_Peripheral_HolderXRealsenseD415.STL" /> -->
        <mesh filename="file:///home/oskars/workspace/ar4_pmb2_ws/install/annin_ar4_description/share/annin_ar4_description/meshes/ar4/J4_Peripheral_HolderXD415v2.STL"/>
      </geometry>
      <material name="">
        <color rgba="1 1 0 1"/>
      </material>
    </visual>
    <collision>
      <geometry>
        <!-- <mesh filename="file://$(find annin_ar4_description)/meshes/ar4/J6_Peripheral_HolderXRealsenseD415.STL" /> -->
        <mesh filename="file:///home/oskars/workspace/ar4_pmb2_ws/install/annin_ar4_description/share/annin_ar4_description/meshes/ar4/J4_Peripheral_HolderXD415v2.STL"/>
      </geometry>
    </collision>
    <inertial>
      <origin xyz="0.0 0.0 0.0"/>
      <mass value="0.08"/>
      <inertia ixx="0.00001" ixy="0.0" ixz="0.0" iyy="0.00001" iyz="0.0" izz="0.00001"/>
    </inertial>
  </link>
  <!-- center of the end effector mounting surface on link_6 -->
  <link name="ar4_ee_link"/>
  <joint name="ar4_ee_joint" type="fixed">
    <parent link="ar4_link_6"/>
    <child link="ar4_ee_link"/>
    <origin rpy="0 0 0" xyz="0 0 0.0"/>
  </joint>
  <link name="ar4_gripper_grasping_link"/>
  <joint name="ar4_gripper_grasping_joint" type="fixed">
    <parent link="ar4_link_6"/>
    <child link="ar4_gripper_grasping_link"/>
    <origin rpy="0 0 0" xyz="0 0 0.1"/>
  </joint>
  <joint name="ar4_gripper_base_joint" type="fixed">
    <origin rpy="-1.5708 0.0 0.0" xyz="0.0 0.0 0.0"/>
    <parent link="ar4_ee_link"/>
    <child link="ar4_gripper_base_link"/>
  </joint>
  <link name="ar4_gripper_base_link">
    <visual>
      <geometry>
        <mesh filename="file:///home/oskars/workspace/ar4_pmb2_ws/install/annin_ar4_description/share/annin_ar4_description/meshes/ar4_gripper/gripper_base_link.stl"/>
      </geometry>
      <material name="">
        <color rgba="1 1 0 1"/>
      </material>
    </visual>
    <collision>
      <geometry>
        <mesh filename="file:///home/oskars/workspace/ar4_pmb2_ws/install/annin_ar4_description/share/annin_ar4_description/meshes/ar4_gripper/gripper_base_link.stl"/>
      </geometry>
    </collision>
    <inertial>
      <origin xyz="-0.00073621 -0.02341392 -0.00435302"/>
      <mass value="0.08"/>
      <inertia ixx="0.00002375" ixy="0.00000002" ixz="-0.00000017" iyy="0.00004082" iyz="-0.00000029" izz="0.00004254"/>
    </inertial>
  </link>
  <link name="ar4_gripper_jaw1_link">
    <visual>
      <geometry>
        <!-- <mesh filename="file://$(find annin_ar4_description)/meshes/ar4_gripper/gripper_jaw1_link.stl" /> -->
        <mesh filename="file:///home/oskars/workspace/ar4_pmb2_ws/install/annin_ar4_description/share/annin_ar4_description/meshes/ar4_soft_gripper/soft_gripper_jaw1_link.stl"/>
      </geometry>
      <material name="">
        <color rgba="1 1 0 1"/>
      </material>
    </visual>
    <collision>
      <geometry>
        <!-- <mesh filename="file://$(find annin_ar4_description)/meshes/ar4_gripper/gripper_jaw1_link.stl" /> -->
        <mesh filename="file:///home/oskars/workspace/ar4_pmb2_ws/install/annin_ar4_description/share/annin_ar4_description/meshes/ar4_soft_gripper/soft_gripper_jaw1_link.stl"/>
      </geometry>
    </collision>
    <inertial>
      <origin xyz="-0.00435839 -0.00469536 0.00757141"/>
      <mass value="0.01"/>
      <inertia ixx="0.00000123" ixy="-0.00000004" ixz="0.00000012" iyy="0.00000115" iyz="0.00000016" izz="0.00000102"/>
    </inertial>
  </link>
  <link name="ar4_gripper_jaw2_link">
    <visual>
      <geometry>
        <!-- <mesh filename="file://$(find annin_ar4_description)/meshes/ar4_gripper/gripper_jaw2_link.stl" /> -->
        <mesh filename="file:///home/oskars/workspace/ar4_pmb2_ws/install/annin_ar4_description/share/annin_ar4_description/meshes/ar4_soft_gripper/soft_gripper_jaw2_link.stl"/>
      </geometry>
      <material name="">
        <color rgba="1 1 0 1"/>
      </material>
    </visual>
    <collision>
      <geometry>
        <!-- <mesh filename="file://$(find annin_ar4_description)/meshes/ar4_gripper/gripper_jaw2_link.stl" /> -->
        <mesh filename="file:///home/oskars/workspace/ar4_pmb2_ws/install/annin_ar4_description/share/annin_ar4_description/meshes/ar4_soft_gripper/soft_gripper_jaw2_link.stl"/>
      </geometry>
    </collision>
    <inertial>
      <origin xyz="-0.00423971 -0.00491236 0.00814582"/>
      <mass value="0.01"/>
      <inertia ixx="0.00000118" ixy="-0.00000004" ixz="0.00000013" iyy="0.00000110" iyz="0.00000013" izz="0.00000101"/>
    </inertial>
  </link>
  <joint name="ar4_gripper_jaw1_joint" type="prismatic">
    <origin rpy="0.0 0.0 0.0" xyz="0.0 -0.036 0"/>
    <!-- <origin xyz="-0.005 -0.036 0" rpy="0.0 0.0 0.0"/> -->
    <parent link="ar4_gripper_base_link"/>
    <child link="ar4_gripper_jaw1_link"/>
    <axis xyz="-1 0 0"/>
    <limit effort="1000" lower="0" upper="0.014" velocity="1.0"/>
    <!-- <limit lower="-0.005" upper="0.009" effort="1000" velocity="1.0"/> -->
  </joint>
  <joint name="ar4_gripper_jaw2_joint" type="prismatic">
    <origin rpy="0.0 -3.141592653589793 0.0" xyz="0.0 -0.036 0"/>
    <!-- <origin xyz="0.005 -0.036 0" rpy="0.0 ${-pi} 0.0"/> -->
    <parent link="ar4_gripper_base_link"/>
    <child link="ar4_gripper_jaw2_link"/>
    <axis xyz="-1 0 0"/>
    <limit effort="1000" lower="0" upper="0.014" velocity="1.0"/>
    <!-- <limit lower="-0.005" upper="0.009" effort="1000" velocity="1.0"/> -->
    <mimic joint="ar4_gripper_jaw1_joint" multiplier="1" offset="0"/>
  </joint>
  <!-- Fix for https://github.com/ros-controls/gz_ros2_control/issues/96 when running in sim -->
  <link name="ar4_dummy_mimic_fix"/>
  <joint name="ar4_gripper_jaw2_joint_mimic" type="fixed">
    <parent link="ar4_gripper_base_link"/>
    <child link="ar4_dummy_mimic_fix"/>
  </joint>
</robot>
